Workbook

Sheet DCF
B2: Discounted Cash Flow Valuation
B3: $ and shares in millions, except per share data
B4: Most recent fiscal year end | D4: 46022 | F4: Discount rate (WACC) | H4: =WACC!E21 -> 0.09531164
B5: End of first fiscal year | D5: =EOMONTH(D4,12) -> 46387 | F5: Share price | H5: 198.79
B6: Most recent quarter end date | D6: 46022 | F6: Share price date | H6: 46066
B7: Valuation date | D7: 46066 | F7: Midyear adjustment? | H7: 0
B8: Portion of First Year Cash Flows | D8: =YEARFRAC(D7,D5) -> 0.88333333
F9: Case active: | H9: ='3 Statement Model'!C12 -> Base case
B10: Unlevered Free Cash Flows
C11: LTM | D11: Actual | E11: Forecasts
B12: Fiscal year ended | C12: =D7 -> 46066 | D12: =D4 -> 46022 | E12: =EOMONTH(D12,12) -> 46387 | F12: =EOMONTH(E12,12) -> 46752 | G12: =EOMONTH(F12,12) -> 47118 | H12: =EOMONTH(G12,12) -> 47483 | I12: =EOMONTH(H12,12) -> 47848
B14: Revenue | C14: =+E14*(1-$D$8)+D14*$D$8 -> 727206.12 | D14: ='3 Statement Model'!E18 -> 716924 | E14: ='3 Statement Model'!F18 -> 805056.43 | F14: ='3 Statement Model'!G18 -> 895555.18 | G14: ='3 Statement Model'!H18 -> 1009191.8 | H14: ='3 Statement Model'!I18 -> 1137247.8 | I14: ='3 Statement Model'!J18 -> 1281552.7
B15: % growth | E15: =E14/D14-1 -> 0.12293134 | F15: =F14/E14-1 -> 0.11241293 | G15: =G14/F14-1 -> 0.1268896 | H15: =H14/G14-1 -> 0.1268896 | I15: =I14/H14-1 -> 0.1268896
B16: EBITDA | C16: =+E16*(1-$D$8)+D16*$D$8 -> 150534.35 | D16: ='3 Statement Model'!E34 -> 145731 | E16: ='3 Statement Model'!F34 -> 186902.6 | F16: ='3 Statement Model'!G34 -> 209981.59 | G16: ='3 Statement Model'!H34 -> 254753.1 | H16: ='3 Statement Model'!I34 -> 291579.09 | I16: ='3 Statement Model'!J34 -> 333636.68
B17: % margin | D17: =D16/D14 -> 0.20327259 | E17: =E16/E14 -> 0.23216087 | F17: =F16/F14 -> 0.23447086 | G17: =G16/G14 -> 0.25243279 | H17: =H16/H14 -> 0.25639012 | I17: =I16/I14 -> 0.26033786
B18: EBIT | C18: =+E18*(1-$D$8)+D18*$D$8 -> 82301.023 | D18: ='3 Statement Model'!E24 -> 79975 | E18: ='3 Statement Model'!F24 -> 99912.342 | F18: ='3 Statement Model'!G24 -> 115972.81 | G18: ='3 Statement Model'!H24 -> 147341.86 | H18: ='3 Statement Model'!I24 -> 166134.82 | I18: ='3 Statement Model'!J24 -> 187312.42
B19: % margin | D19: =D18/D14 -> 0.11155297 | E19: =E18/E14 -> 0.12410601 | F19: =F18/F14 -> 0.12949823 | G19: =G18/G14 -> 0.14599985 | H19: =H18/H14 -> 0.14608499 | I19: =I18/I14 -> 0.14616053
B21: Tax on EBIT | D21: =D22*D18 -> 15686.642 | E21: =E22*E18 -> 18523.748 | F21: =F22*F18 -> 21744.902 | G21: =G22*G18 -> 27405.585 | H21: =H22*H18 -> 30901.077 | I21: =I22*I18 -> 34840.11
B22: Tax rate | D22: ='3 Statement Model'!E43 -> 0.19614432 | E22: ='3 Statement Model'!F43 -> 0.1854 | F22: ='3 Statement Model'!G43 -> 0.1875 | G22: ='3 Statement Model'!H43 -> 0.186 | H22: ='3 Statement Model'!I43 -> 0.186 | I22: ='3 Statement Model'!J43 -> 0.186
B23: NOPAT | D23: =D18*(1-D22) -> 64288.358 | E23: =E18*(1-E22) -> 81388.594 | F23: =F18*(1-F22) -> 94227.91 | G23: =G18*(1-G22) -> 119936.27 | H23: =H18*(1-H22) -> 135233.75 | I23: =I18*(1-I22) -> 152472.31
B25: Depreciation & amortization | D25: ='3 Statement Model'!E33 -> 65756 | E25: ='3 Statement Model'!F33 -> 86990.258 | F25: ='3 Statement Model'!G33 -> 94008.777 | G25: ='3 Statement Model'!H33 -> 107411.25 | H25: ='3 Statement Model'!I33 -> 125444.27 | I25: ='3 Statement Model'!J33 -> 146324.26
B26: Changes in net working capital | E26: =D32-E32 -> 13721.087 | F26: =E32-F32 -> 12679.898 | G26: =F32-G32 -> 15743.302 | H26: =G32-H32 -> 19553.089 | I26: =H32-I32 -> 22034.173
B27: Capital expenditures | E27: ='3 Statement Model'!F85 -> -178185.02 | F27: ='3 Statement Model'!G85 -> -179424.13 | G27: ='3 Statement Model'!H85 -> -195389.49 | H27: ='3 Statement Model'!I85 -> -220182.38 | I27: ='3 Statement Model'!J85 -> -248121.24
B28: as % of revenue | E28: =E27/E14 -> -0.22133234 | F28: =F27/F14 -> -0.20034961 | G28: =G27/G14 -> -0.19360986 | H28: =H27/H14 -> -0.19360986 | I28: =I27/I14 -> -0.19360986
B30: Unlevered free cash flows (UFCF) | E30: =E23+E25+E26+E27 -> 3914.9193 | F30: =F23+F25+F26+F27 -> 21492.454 | G30: =G23+G25+G26+G27 -> 47701.331 | H30: =H23+H25+H26+H27 -> 60048.717 | I30: =I23+I25+I26+I27 -> 72709.508
B32: Net working capital (WC Assets - WC liabilities) | D32: =SUM('3 Statement Model'!E49,'3 Statement Model'!E50)-SUM('3 Statement Model'!E55,'3 Statement Model'!E56,'3 Statement Model'!E57) -> -111951 | E32: =SUM('3 Statement Model'!F49,'3 Statement Model'!F50)-SUM('3 Statement Model'!F55,'3 Statement Model'!F56,'3 Statement Model'!F57) -> -125672.09 | F32: =SUM('3 Statement Model'!G49,'3 Statement Model'!G50)-SUM('3 Statement Model'!G55,'3 Statement Model'!G56,'3 Statement Model'!G57) -> -138351.99 | G32: =SUM('3 Statement Model'!H49,'3 Statement Model'!H50)-SUM('3 Statement Model'!H55,'3 Statement Model'!H56,'3 Statement Model'!H57) -> -154095.29 | H32: =SUM('3 Statement Model'!I49,'3 Statement Model'!I50)-SUM('3 Statement Model'!I55,'3 Statement Model'!I56,'3 Statement Model'!I57) -> -173648.38 | I32: =SUM('3 Statement Model'!J49,'3 Statement Model'!J50)-SUM('3 Statement Model'!J55,'3 Statement Model'!J56,'3 Statement Model'!J57) -> -195682.55
B33: as % of revenue | D33: =D32/D14 -> -0.15615463 | E33: =E32/E14 -> -0.15610345 | F33: =F32/F14 -> -0.15448739 | G33: =G32/G14 -> -0.15269177 | H33: =H32/H14 -> -0.15269177 | I33: =I32/I14 -> -0.15269177
B35: ="Present value of UFCF on "&TEXT(D7,"mmm dd, yyyy")&" valuation date" -> Present value of UFCF on Feb 13, 2026 valuation date
D36: Val date | E36: Yr 1 - Stub | F36: Year 2 | G36: Year 3 | H36: Year 4 | I36: Year 5
B37: Date for discounting cash flows | D37: =D7 -> 46066 | E37: =IF($H$7=1,AVERAGE(E12,D37),E12) -> 46387 | F37: =IF($H$7=1,AVERAGE(F12,E12),F12) -> 46752 | G37: =IF($H$7=1,AVERAGE(G12,F12),G12) -> 47118 | H37: =IF($H$7=1,AVERAGE(H12,G12),H12) -> 47483 | I37: =IF($H$7=1,AVERAGE(I12,H12),I12) -> 47848
B38: Unlevered free cash flows (UFCF) stub adjusted | C38: =D8 -> 0.88333333 | E38: =E30*C38 -> 3458.1788 | F38: =F30 -> 21492.454 | G38: =G30 -> 47701.331 | H38: =H30 -> 60048.717 | I38: =I30 -> 72709.508
B39: Present value of of unlevered free cash flows | E39: =E38/(1+$H$4)^((E37-$D$7)/365) -> 3192.0959 | F39: =F38/(1+$H$4)^((F37-$D$7)/365) -> 18112.433 | G39: =G38/(1+$H$4)^((G37-$D$7)/365) -> 36692.327 | H39: =H38/(1+$H$4)^((H37-$D$7)/365) -> 42170.698 | I39: =I38/(1+$H$4)^((I37-$D$7)/365) -> 46618.743
B41: Terminal value - growth in perpetuity approach | E41: Terminal value - EBITDA multiple approach
B42: Long term growth rate | C42: 0.023 | E42: Terminal year EBITDA | I42: =I16 -> 333636.68
B43: =YEAR(I12)&" FCF x (1+g)" -> 2030 FCF x (1+g) | C43: =I38*(1+C42) -> 74381.827 | E43: EBITDA multiple | I43: 10.3
B44: ="Terminal value in "&YEAR(I12) -> Terminal value in 2030 | C44: =C43/(H4-C42) -> 1028628.7 | E44: ="Terminal value in "&YEAR(I12) -> Terminal value in 2030 | I44: =I42*I43 -> 3436457.8
B45: Present value of terminal value | C45: =C44/(1+H4)^((I37-$D$37)/365) -> 659520.02 | E45: Present value of terminal value | I45: =I44/(1+H4)^((I37-D37)/365) -> 2203334.2
B46: Present value of stage 1 cash flows | C46: =SUM(E39:I39) -> 146786.3 | E46: Present value of stage 1 cash flows | I46: =C46 -> 146786.3
B47: Total enterprise value (TEV) | C47: =C46+C45 -> 806306.32 | E47: Enterprise value (stage 1 + 2) | I47: =SUM(I45:I46) -> 2350120.5
B49: Terminal value as % of TEV | C49: =C45/$C$47 -> 0.81795219 | E49: Terminal value as % of TEV | I49: =+I45/I47 -> 0.93754095
...

Sheet WACC
B2: WACC Buildup
B3: $ and shares in millions, except per share data
B4: Cost of capital assumptions
E5: Source
B6: Cost of debt | C6: 0.03988 | E6: Capital IQ - YTM on 4.1% 11/30
B7: Tax rate | C7: ='3 Statement Model'!J43 -> 0.186 | E7: From terminal year of UFCF forecast
B8: Cost of debt (after tax) | C8: =C6*(1-C7) -> 0.03246232 | E8: Cost of debt x (1 - tax rate)
B10: Risk free rate | C10: 0.03611 | E10: WSJ: 5 Year US Treasury Yield
B11: Beta | C11: =IF(C32="Observed",C34,C35) -> 1.38 | E11: Bloomberg 2 year weekly adjusted beta
B12: Market risk premium | C12: 0.0417 | E12: Damodaran implied ERP 2/26
B13: Cost of equity | C13: =C10+C11*C12 -> 0.093656 | E13: RfR + Beta x MRP
B15: Capital weights (capital structure)
D16: Target
C17: Current | D17: (override) | E17: % of total
B18: Equity | C18: =DCF!I61*DCF!H5 -> 2178225.7 | E18: =IF(D18,D18,C18/(C18+C19)) -> 1.0270557
B19: Debt | C19: ='3 Statement Model'!E59-'3 Statement Model'!E48 -> -57381 | D19: =1-D18 -> 1 | E19: =1-E18 -> -0.027055729
B21: Cost of capital (WACC) | E21: =C8*E19+C13*E18 -> 0.09531164
B23: WACC sensitivity to MRP and Beta
D24: Beta
C25: =E21 -> 0.09531164 | D25: =E25-0.1 -> 1.28 | E25: 1.38 | F25: =E25+0.1 -> 1.48
C26: =C27-0.005 -> 0.0317 | D26: 0.061013495 | E26: 0.065908826 | F26: 0.070804156
B27: Market | C27: =C28-0.005 -> 0.0367 | D27: 0.066447312 | E27: 0.071886568 | F27: 0.077325824
B28: Risk | C28: 0.0417 | D28: 0.071881129 | E28: 0.077864311 | F28: 0.083847492
B29: Premium | C29: =C28+0.005 -> 0.0467 | D29: 0.077314946 | E29: 0.083842053 | F29: 0.090369161
C30: =C29+0.005 -> 0.0517 | D30: 0.082748763 | E30: 0.089819796 | F30: 0.096890829
B32: Select Beta for model | C32: Observed
B34: Observed | C34: 1.38 | D34: Bloomberg 2 year weekly adjusted beta
B35: Industry beta | C35: =C46 -> 1.0430125 | D35: From schedule below
B37: Industry beta
C39: Observed b | D39: Share price | E39: Dil. shares | F39: Market cap | G39: Net Debt | H39: Tax rate | I39: Delev. b
B40: Microsoft MSFT | C40: 1.08 | D40: 401.32 | E40: 7425.6 | F40: =D40*E40 -> 2980041.8 | G40: =40262-89462 -> -49200 | H40: 0.1763 | I40: =C40/(1+(1-H40)*(G40)/F40) -> 1.0948896
B41: Alphabet (GOOG) | C41: 1.09 | D41: 305.72 | E41: 12390 | F41: =D41*E41 -> 3787870.8 | G41: =23602-98496 -> -74894 | H41: 0.1678 | I41: =C41/(1+(1-H41)*(G41)/F41) -> 1.1082352
B42: Walmart (WMT) | C42: 0.67 | D42: 133.89 | E42: 7991.1 | F42: =D42*E42 -> 1069928.4 | G42: =53433-10582 -> 42851 | H42: 0.236 | I42: =C42/(1+(1-H42)*(G42)/F42) -> 0.6501077
B43: Amazon (AMZN) | C43: =C34 -> 1.38 | F43: =C18 -> 2178225.7 | G43: =C19 -> -57381 | H43: =C7 -> 0.186 | I43: =C43/(1+(1-H43)*(G43)/F43) -> 1.4102401
B45: Industry average delevered beta | C45: =AVERAGE(I40:I43) -> 1.0658681
B46: =B43&" beta" -> Amazon (AMZN) beta | C46: =C45*(1+(1-H43)*(G43)/F43) -> 1.0430125

Sheet 3 Statement Model
B2: ="Financial Statement Model for "&C5 -> Financial Statement Model for Amazon
B3: $ and shares in millions, except per share data
B5: Company name | C5: Amazon
B6: Ticker | C6: AMZN
B7: Circ break 1=off, 0=on | C7: 1
B8: Latest closing share price | C8: 198.79
B9: Latest closing share price date | C9: 46066
B10: Latest fiscal year end date | C10: 46022
B11: Shares outstanding (millions) | C11: 10734.921
B12: Select an operating scenario: | C12: Base case
B14: INCOME STATEMENT
B15: Fiscal year | C15: =D15-1 -> 2023 | D15: =E15-1 -> 2024 | E15: =YEAR(C10) -> 2025 | F15: =E15+1 -> 2026 | G15: =F15+1 -> 2027 | H15: =G15+1 -> 2028 | I15: =H15+1 -> 2029 | J15: =I15+1 -> 2030
B16: Fiscal year end date | C16: =EOMONTH(D16,-12) -> 45291 | D16: =EOMONTH(E16,-12) -> 45657 | E16: =C10 -> 46022 | F16: =EOMONTH(E16,12) -> 46387 | G16: =EOMONTH(F16,12) -> 46752 | H16: =EOMONTH(G16,12) -> 47118 | I16: =EOMONTH(H16,12) -> 47483 | J16: =EOMONTH(I16,12) -> 47848
B18: Revenue - products | C18: =255887+318898 -> 574785 | D18: =272311+365648 -> 637959 | E18: =296266+420658 -> 716924 | F18: =E18*(1+F39) -> 805056.43 | G18: =F18*(1+G39) -> 895555.18 | H18: =G18*(1+H39) -> 1009191.8 | I18: =H18*(1+I39) -> 1137247.8 | J18: =I18*(1+J39) -> 1281552.7
B19: Cost of Sales | C19: =-304739-90619 -> -395358 | D19: =-326288-98505 -> -424793 | E19: =-356414-109074 -> -465488 | F19: =F20-F18 -> -522481.62 | G19: =G20-G18 -> -573155.32 | H19: =H20-H18 -> -635790.85 | I19: =I20-I18 -> -716466.09 | J19: =J20-J18 -> -807378.19
B20: Gross Profit | C20: =SUM(C18:C19) -> 179427 | D20: =SUM(D18:D19) -> 213166 | E20: =SUM(E18:E19) -> 251436 | F20: =F18*F40 -> 282574.81 | G20: =G18*G40 -> 322399.86 | H20: =H18*H40 -> 373400.97 | I20: =I18*I40 -> 420781.67 | J20: =J18*J40 -> 474174.49
B21: Selling, general & administrative | C21: =-44370-11816 -> -56186 | D21: =-43907-11359 -> -55266 | E21: =-47129-11172 -> -58301 | F21: =-F18*F42 -> -61141 | G21: =-G18*G42 -> -66853 | H21: =-H18*H42 -> -66853 | I21: =-I18*I42 -> -75335.95 | J21: =-J18*J42 -> -84895.299
B22: R&D: Technology and Infrastructure | C22: -85622 | D22: -88544 | E22: -108521 | F22: =F18*F41*-1 -> -120758.46 | G22: =G18*G41*-1 -> -138811.05 | H22: =H18*H41*-1 -> -158443.12 | I22: =I18*I41*-1 -> -178547.9 | J22: =J18*J41*-1 -> -201203.77
B23: Other operating expense, net | C23: -767 | D23: -763 | E23: -4639 | F23: =$D$23 -> -763 | G23: =$D$23 -> -763 | H23: =$D$23 -> -763 | I23: =$D$23 -> -763 | J23: =$D$23 -> -763
B24: Operating profit (EBIT) | C24: =SUM(C20:C23) -> 36852 | D24: =SUM(D20:D23) -> 68593 | E24: =SUM(E20:E23) -> 79975 | F24: =SUM(F20:F23) -> 99912.342 | G24: =SUM(G20:G23) -> 115972.81 | H24: =SUM(H20:H23) -> 147341.86 | I24: =SUM(I20:I23) -> 166134.82 | J24: =SUM(J20:J23) -> 187312.42
B25: Interest income | C25: 2949 | D25: 4677 | E25: 4381 | F25: =F138 -> 3512.4978 | G25: =G138 -> 3399.5168 | H25: =H138 -> 3823.678 | I25: =I138 -> 4665.8363 | J25: =J138 -> 5755.9661
B26: Interest expense | C26: -3182 | D26: -2406 | E26: -2274 | F26: =F134 -> -2524.4321 | G26: =G134 -> -2524.4321 | H26: =H134 -> -2524.4321 | I26: =I134 -> -2524.4321 | J26: =J134 -> -2524.4321
B27: Other expense, net | C27: 938 | D27: -2250 | E27: 15229 | F27: =E27 -> 15229 | G27: =F27 -> 15229 | H27: =G27 -> 15229 | I27: =H27 -> 15229 | J27: =I27 -> 15229
B28: Pretax profit | C28: =SUM(C24:C27) -> 37557 | D28: =SUM(D24:D27) -> 68614 | E28: =SUM(E24:E27) -> 97311 | F28: =SUM(F24:F27) -> 116129.41 | G28: =SUM(G24:G27) -> 132076.9 | H28: =SUM(H24:H27) -> 163870.1 | I28: =SUM(I24:I27) -> 183505.23 | J28: =SUM(J24:J27) -> 205772.96
B29: Taxes | C29: -7120 | D29: -9265 | E29: -19087 | F29: =-F43*F28 -> -21530.392 | G29: =-G43*G28 -> -24764.418 | H29: =-H43*H28 -> -30479.839 | I29: =-I43*I28 -> -34131.972 | J29: =-J43*J28 -> -38273.77
B30: Equity method investment, net of tax | C30: -12 | D30: -101 | E30: -554
B31: Net income | C31: =SUM(C28:C30) -> 30425 | D31: =SUM(D28:D30) -> 59248 | E31: =SUM(E28:E30) -> 77670 | F31: =SUM(F28:F30) -> 94599.016 | G31: =SUM(G28:G30) -> 107312.48 | H31: =SUM(H28:H30) -> 133390.26 | I31: =SUM(I28:I30) -> 149373.26 | J31: =SUM(J28:J30) -> 167499.19
B33: Depreciation & amortization | C33: 48663 | D33: 52795 | E33: 65756 | F33: =F109 -> 86990.258 | G33: =G109 -> 94008.777 | H33: =H109 -> 107411.25 | I33: =I109 -> 125444.27 | J33: =J109 -> 146324.26
B34: EBITDA | C34: =C24+C33 -> 85515 | D34: =D24+D33 -> 121388 | E34: =E24+E33 -> 145731 | F34: =F24+F33 -> 186902.6 | G34: =G24+G33 -> 209981.59 | H34: =H24+H33 -> 254753.1 | I34: =I24+I33 -> 291579.09 | J34: =J24+J33 -> 333636.68
B35: Stock based compensation | C35: 24023 | D35: 22011 | E35: 19467 | F35: =E35*(1+F39) -> 21860.104 | G35: =F35*(1+G39) -> 24317.463 | H35: =G35*(1+H39) -> 27403.096 | I35: =H35*(1+I39) -> 30880.264 | J35: =I35*(1+J39) -> 34798.648
B36: Adjusted EBITDA | C36: =SUM(C34:C35) -> 109538 | D36: =SUM(D34:D35) -> 143399 | E36: =SUM(E34:E35) -> 165198 | F36: =SUM(F34:F35) -> 208762.7 | G36: =SUM(G34:G35) -> 234299.05 | H36: =SUM(H34:H35) -> 282156.2 | I36: =SUM(I34:I35) -> 322459.35 | J36: =SUM(J34:J35) -> 368435.33
B38: Growth rates & margins
B39: Revenue growth | D39: =D18/C18-1 -> 0.10990892 | E39: =E18/D18-1 -> 0.12377755 | F39: =F156 -> 0.12293134 | G39: =G156 -> 0.11241293 | H39: =H156 -> 0.1268896 | I39: =I156 -> 0.1268896 | J39: =J156 -> 0.1268896
B40: Gross profit margin | C40: =C20/C18 -> 0.31216368 | D40: =D20/D18 -> 0.33413746 | E40: =E20/E18 -> 0.350715 | F40: =F157 -> 0.351 | G40: =G157 -> 0.36 | H40: =H157 -> 0.37 | I40: =I157 -> 0.37 | J40: =J157 -> 0.37
B41: R&D % of sales | C41: =C22/C18*-1 -> 0.14896353 | D41: =D22/D18*-1 -> 0.13879262 | E41: =E22/E18*-1 -> 0.1513703 | F41: =F171 -> 0.15 | G41: =G171 -> 0.155 | H41: =H171 -> 0.157 | I41: =I171 -> 0.157 | J41: =J171 -> 0.157
B42: SG&A % of sales | C42: =C21/C18*-1 -> 0.097751333 | D42: =D21/D18*-1 -> 0.086629392 | E42: =E21/E18*-1 -> 0.081321033 | F42: =F159 -> 0.075946229 | G42: =G159 -> 0.074649783 | H42: =H159 -> 0.066244096 | I42: =I159 -> 0.066244096 | J42: =J159 -> 0.066244096
B43: Tax rate | C43: =-C29/C28 -> 0.18957851 | D43: =-D29/D28 -> 0.13503075 | E43: =-E29/E28 -> 0.19614432 | F43: 0.1854 | G43: 0.1875 | H43: 0.186 | I43: =H43 -> 0.186 | J43: =I43 -> 0.186
B45: BALANCE SHEET
B46: =B15 -> Fiscal year | D46: =D15 -> 2024 | E46: =E15 -> 2025 | F46: =F15 -> 2026 | G46: =G15 -> 2027 | H46: =H15 -> 2028 | I46: =I15 -> 2029 | J46: =J15 -> 2030
B47: =B16 -> Fiscal year end date | D47: =D16 -> 45657 | E47: =E16 -> 46022 | F47: =F16 -> 46387 | G47: =G16 -> 46752 | H47: =H16 -> 47118 | I47: =I16 -> 47483 | J47: =J16 -> 47848
...
